[2023-07-07 18:46:23,366: INFO: main]: 
********************
[2023-07-07 18:46:23,366: INFO: main]: >>>>> stage Main started <<<<<
[2023-07-07 18:46:23,843: ERROR: main]: Run (ID 'a5261814be584ac898c6b6268a9568e4') failed
Traceback (most recent call last):
  File "src/main.py", line 32, in <module>
    main()
  File "src/main.py", line 23, in main
    mlflow.run(".", "get_data", use_conda=False)
  File "C:\Users\123sa\anaconda3\envs\env\lib\site-packages\mlflow\projects\__init__.py", line 360, in run
    _wait_for(submitted_run_obj)
  File "C:\Users\123sa\anaconda3\envs\env\lib\site-packages\mlflow\projects\__init__.py", line 377, in _wait_for
    raise ExecutionException("Run (ID '%s') failed" % run_id)
mlflow.exceptions.ExecutionException: Run (ID 'a5261814be584ac898c6b6268a9568e4') failed
